Workbook

Sheet Inkomna svar
A1: Frågeområden och frågor | B1: Enkät 1 | C1: Enkät 2 | D1: Enkät 3 | E1: Enkät 4 | F1: Enkät 5 | G1: Enkät 6 | H1: Enkät 7 | I1: Enkät 8 | J1: Gen. värde | K1: Gen. %
A2: Trivsel | K2: =AVERAGE(K3:K10) -> 0.8203125
A3: Jag känner mig glad på väg till arbetet | B3: 6 | C3: 6 | D3: 6 | E3: 6 | F3: 6 | G3: 6 | H3: 6 | I3: 6 | J3: =AVERAGE(B3:I3) -> 6 | K3: =SUM(J3/6) -> 1
A4: Jag trivs med mina arbetskamrater | B4: 4 | C4: 5 | D4: 6 | E4: 5 | F4: 6 | G4: 6 | H4: 5 | I4: 6 | J4: =AVERAGE(B4:I4) -> 5.375 | K4: =SUM(J4/6) -> 0.89583333
A5: Jag har ett intressant och stimulerande arbete | B5: 4 | C5: 4 | D5: 6 | E5: 4 | F5: 6 | G5: 2 | H5: 4 | I5: 4 | J5: =AVERAGE(B5:I5) -> 4.25 | K5: =SUM(J5/6) -> 0.70833333
A6: Jag vet vad som förväntas av mig | B6: 5 | C6: 5 | D6: 6 | E6: 4 | F6: 5 | G6: 5 | H6: 4 | I6: 5 | J6: =AVERAGE(B6:I6) -> 4.875 | K6: =SUM(J6/6) -> 0.8125
A7: Jag har material/verktyg som krävs för att jag ska kunna göra ett bra jobb | B7: 3 | C7: 4 | D7: 6 | E7: 5 | F7: 6 | G7: 5 | H7: 3 | I7: 6 | J7: =AVERAGE(B7:I7) -> 4.75 | K7: =SUM(J7/6) -> 0.79166667
A8: Dagligen får jag möjlighet att göra det som jag är bäst på | B8: 4 | C8: 5 | D8: 6 | E8: 5 | F8: 5 | G8: 4 | H8: 4 | I8: 4 | J8: =AVERAGE(B8:I8) -> 4.625 | K8: =SUM(J8/6) -> 0.77083333
A9: Någon på jobbet bryr sig om mig som person och hur jag mår | B9: 4 | C9: 5 | D9: 6 | E9: 5 | F9: 5 | G9: 6 | H9: 3 | I9: 5 | J9: =AVERAGE(B9:I9) -> 4.875 | K9: =SUM(J9/6) -> 0.8125
A10: Under de senaste veckorna har jag fått bekräftelse eller beröm för mitt arbete | B10: 4 | C10: 3 | D10: 6 | E10: 6 | F10: 6 | G10: 3 | H10: 4 | I10: 5 | J10: =AVERAGE(B10:I10) -> 4.625 | K10: =SUM(J10/6) -> 0.77083333
A12: Delaktighet | K12: =AVERAGE(K13:K18) -> 0.76041667
A13: Vi uppmuntras att vara delaktiga i frågor som rör arbetsplatsen | B13: 2 | C13: 4 | D13: 6 | E13: 4 | F13: 6 | G13: 3 | H13: 5 | I13: 4 | J13: =AVERAGE(B13:I13) -> 4.25 | K13: =SUM(J13/6) -> 0.70833333
A14: Öppna, fria diskussioner kring arbetet kan föras på arbetsplatsen | B14: 4 | C14: 5 | D14: 6 | E14: 6 | F14: 6 | G14: 5 | H14: 5 | I14: 5 | J14: =AVERAGE(B14:I14) -> 5.25 | K14: =SUM(J14/6) -> 0.875
A15: Man lyssnar på mig och man tar till sig mina synpunkter och idéer | B15: 5 | C15: 4 | D15: 6 | E15: 5 | F15: 5 | G15: 3 | H15: 4 | I15: 5 | J15: =AVERAGE(B15:I15) -> 4.625 | K15: =SUM(J15/6) -> 0.77083333
A16: Jag kan påverka innehållet i mina arbetsuppgifter | B16: 2 | C16: 3 | D16: 6 | E16: 4 | F16: 5 | G16: 4 | H16: 3 | I16: 4 | J16: =AVERAGE(B16:I16) -> 3.875 | K16: =SUM(J16/6) -> 0.64583333
A17: Företagets mål får mig att känna att mitt arbete är viktigt | B17: 4 | C17: 4 | D17: 6 | E17: 6 | F17: 6 | G17: 5 | H17: 4 | I17: 5 | J17: =AVERAGE(B17:I17) -> 5 | K17: =SUM(J17/6) -> 0.83333333
A18: Jag har inflytande över hur min arbetstid förläggs | B18: 4 | C18: 4 | D18: 6 | E18: 4 | F18: 4 | G18: 3 | H18: 5 | I18: 5 | J18: =AVERAGE(B18:I18) -> 4.375 | K18: =SUM(J18/6) -> 0.72916667
A20: Arbetsledning | K20: =AVERAGE(K21:K26) -> 0.85069444
A21: Min relation och mitt samarbete med närmaste chefen är god | B21: 5 | C21: 5 | D21: 6 | E21: 6 | F21: 6 | G21: 6 | H21: 5 | I21: 5 | J21: =AVERAGE(B21:I21) -> 5.5 | K21: =SUM(J21/6) -> 0.91666667
A22: Jag får återkoppling av min chef på det arbete jag utför | B22: 4 | C22: 5 | D22: 6 | E22: 5 | F22: 5 | G22: 4 | H22: 5 | I22: 4 | J22: =AVERAGE(B22:I22) -> 4.75 | K22: =SUM(J22/6) -> 0.79166667
A23: Vi uppmuntras av vår chef att förbättra våra resultat | B23: 5 | C23: 5 | D23: 6 | E23: 5 | F23: 5 | G23: 6 | H23: 5 | I23: 5 | J23: =AVERAGE(B23:I23) -> 5.25 | K23: =SUM(J23/6) -> 0.875
A24: Chefen har förmågan att få oss att arbeta för att nå gemensamma mål | B24: 3 | C24: 5 | D24: 6 | E24: 6 | F24: 5 | G24: 6 | H24: 5 | I24: 5 | J24: =AVERAGE(B24:I24) -> 5.125 | K24: =SUM(J24/6) -> 0.85416667
A25: Min chef är positiv till utveckling och nytänkande | B25: 6 | C25: 5 | D25: 6 | E25: 6 | F25: 6 | G25: 5 | H25: 5 | I25: 6 | J25: =AVERAGE(B25:I25) -> 5.625 | K25: =SUM(J25/6) -> 0.9375
A26: Jag får sällan avbryta mina arbetsuppgifter för att annan arbetsuppgift måste prioriteras | B26: 5 | C26: 3 | D26: 6 | E26: 4 | F26: 5 | G26: 3 | H26: 4 | I26: 5 | J26: =AVERAGE(B26:I26) -> 4.375 | K26: =SUM(J26/6) -> 0.72916667
A28: Information | K28: =AVERAGE(K29:K31) -> 0.75
A29: Jag får den information jag behöver för att kunna utföra mitt arbete | B29: 5 | C29: 5 | D29: 6 | E29: 6 | F29: 6 | G29: 5 | H29: 4 | I29: 6 | J29: =AVERAGE(B29:I29) -> 5.375 | K29: =SUM(J29/6) -> 0.89583333
A30: Jag tycker att jag får tillräckligt med information om förändringar inom verksamheten och företagets utveckling etc | B30: 5 | C30: 3 | D30: 6 | E30: 6 | F30: 5 | G30: 5 | H30: 2 | I30: 5 | J30: =AVERAGE(B30:I30) -> 4.625 | K30: =SUM(J30/6) -> 0.77083333
A31: Jag tycker att vi har en bra mötesstruktur med bra mötesintervall | B31: 2 | C31: 3 | D31: 6 | E31: 4 | F31: 5 | G31: 1 | H31: 3 | I31: 4 | J31: =AVERAGE(B31:I31) -> 3.5 | K31: =SUM(J31/6) -> 0.58333333
A33: Arbetsbelastning och fysisk arbetsmiljö | K33: =AVERAGE(K34:K39) -> 0.79513889
A34: Jag har en god balans mellan arbete, fritid och familjeliv | B34: 4 | C34: 4 | D34: 5 | E34: 5 | F34: 5 | G34: 6 | H34: 6 | I34: 5 | J34: =AVERAGE(B34:I34) -> 5 | K34: =SUM(J34/6) -> 0.83333333
A35: Jag kan hantera stress som ibland uppkommer i arbetet | B35: 4 | C35: 5 | D35: 5 | E35: 5 | F35: 6 | G35: 6 | H35: 3 | I35: 6 | J35: =AVERAGE(B35:I35) -> 5 | K35: =SUM(J35/6) -> 0.83333333
A36: Jag har möjlighet till stöd och hjälp vid hög arbetsbelastning | B36: 4 | C36: 4 | D36: 6 | E36: 4 | F36: 5 | G36: 6 | H36: 4 | I36: 5 | J36: =AVERAGE(B36:I36) -> 4.75 | K36: =SUM(J36/6) -> 0.79166667
A37: Jag har de hjälpmedel och den skyddsutrustning som jag behöver för att utföra mitt arbete | B37: 4 | C37: 5 | D37: 6 | E37: 6 | F37: 5 | G37: 5 | H37: 3 | I37: 6 | J37: =AVERAGE(B37:I37) -> 5 | K37: =SUM(J37/6) -> 0.83333333
A38: Jag upplever att de riskbedömningar som görs på arbetsmiljön är tillräckligt omfattande | B38: 2 | C38: 4 | D38: 4 | E38: 5 | F38: 6 | G38: 5 | H38: 2 | I38: 5 | J38: =AVERAGE(B38:I38) -> 4.125 | K38: =SUM(J38/6) -> 0.6875
A39: Jag upplever att företaget förespråkar vikten av friskvårdsaktiviteter | B39: 2 | C39: 5 | D39: 4 | E39: 6 | F39: 6 | G39: 5 | H39: 5 | I39: 5 | J39: =AVERAGE(B39:I39) -> 4.75 | K39: =SUM(J39/6) -> 0.79166667
A41: Utvecklingsmöjligheter och kompetensutveckling | K41: =AVERAGE(K42:K47) -> 0.69791667
A42: Min kompetens tas tillvara på arbetsplatsen | B42: 6 | C42: 5 | D42: 5 | E42: 5 | F42: 5 | G42: 3 | H42: 3 | I42: 4 | J42: =AVERAGE(B42:I42) -> 4.5 | K42: =SUM(J42/6) -> 0.75
A43: På arbetsplatsen uppmuntrar man min utveckling | B43: 4 | C43: 4 | D43: 5 | E43: 5 | F43: 5 | G43: 5 | H43: 3 | I43: 5 | J43: =AVERAGE(B43:I43) -> 4.5 | K43: =SUM(J43/6) -> 0.75
A44: Under senaste året har jag haft möjlighet att lära mig något nytt och utvecklas i mitt arbete | B44: 3 | C44: 5 | D44: 6 | E44: 3 | F44: 5 | G44: 6 | H44: 3 | I44: 5 | J44: =AVERAGE(B44:I44) -> 4.5 | K44: =SUM(J44/6) -> 0.75
A45: Under det senaste året har jag diskuterat min utveckling med någon på arbetet | B45: 1 | C45: 3 | D45: 6 | E45: 3 | F45: 5 | G45: 5 | H45: 2 | I45: 5 | J45: =AVERAGE(B45:I45) -> 3.75 | K45: =SUM(J45/6) -> 0.625
...

Sheet Sammanställning
A1: Frågeområde | B1: Värde
A2: Trivsel | B2: ='Inkomna svar'!$K$2 -> 0.8203125
A3: Delaktighet | B3: ='Inkomna svar'!$K$12 -> 0.76041667
A4: Arbetsledning | B4: ='Inkomna svar'!$K$20 -> 0.85069444
A5: Information | B5: ='Inkomna svar'!$K$28 -> 0.75
A6: Arbetsbelastning och fysisk arbetsmiljö | B6: ='Inkomna svar'!$K$33 -> 0.79513889
A7: Utvecklingsmöjligheter och kompetensutveckling | B7: ='Inkomna svar'!$K$41 -> 0.69791667
A8: Mobbning, trakasserier | B8: ='Inkomna svar'!$K$49 -> 0.66435185
A9: Förbättringsarbete | B9: ='Inkomna svar'!$K$53 -> 0.63888889
A10: Helhetsbedömning | B10: ='Inkomna svar'!$K$64 -> 0.85416667
A12: Summering | B12: =AVERAGE(B2:B10) -> 0.75909851

Sheet Info
A1: Information om Analys och bedömningsskalor
A3: Frågeområden
A4: Värden under 64,5% = mycket missnöjd och måste förbättras
A5: Värden under 74,5% = lite missnöjd och bör förbättras
A6: Värden över 74,5% = tillräckligt nöjd eller mycket nöjd
A8: Helhetsbedömning (baseras på NMI-frågor)
A9: Värden under 65% = mycket missnöjd och måste förbättras
A10: Värden under 80% = lite missnöjd och bör förbättras
A11: Värden över 80% = tillräckligt nöjd eller mycket nöjd
